video: Full-Text Search with Auto Complete - Python Flask & ElasticSearch
https://www.youtube.com/watch?v=-KjE1JmFVNY

code: https://github.com/ahnaf-zamil/flask-elasticsearch-autocomplete/tree/master


> NOTE: This demo is not working yet.
> 
> error from `$ python loader.py`
> ```
> Traceback (most recent call last):
>  File "/opt/anaconda3/lib/python3.8/site-packages/urllib3/connection.py", line 174, in _new_conn
>    conn = connection.create_connection(
>  File "/opt/anaconda3/lib/python3.8/site-packages/urllib3/util/?connection.py", line 95, in create_connection
>    raise err
>  File "/opt/anaconda3/lib/python3.8/site-packages/urllib3/util/connection.py", line 85, in create_connection
>    sock.connect(sa)
> ConnectionRefusedError: [Errno 61] Connection refused
>
> During handling of the above exception, another exception occurred:
>
> Traceback (most recent call last):
>  File "/opt/anaconda3/lib/python3.8/site-packages/elasticsearch/connection/http_urllib3.py", line 255, in perform_request
>    response = self.pool.urlopen(
>  File "/opt/anaconda3/lib/python3.8/site-packages/urllib3/connectionpool.py", line 802, in urlopen
>    retries = retries.increment(
>  File "/opt/anaconda3/lib/python3.8/site-packages/urllib3/util/retry.py", line 527, in increment
>    raise six.reraise(type(error), error, _stacktrace)
>  File "/opt/anaconda3/lib/python3.8/site-packages/urllib3/packages/six.py", line 770, in reraise
>    raise value
>  File "/opt/anaconda3/lib/python3.8/site-packages/urllib3/connectionpool.py", line 716, in urlopen
>    httplib_response = self._make_request(
>  File "/opt/anaconda3/lib/python3.8/site-packages/urllib3/connectionpool.py", line 404, in _make_request
>    self._validate_conn(conn)
>  File "/opt/anaconda3/lib/python3.8/site-packages/urllib3/connectionpool.py", line 1061, in _validate_conn
>    conn.connect()
>  File "/opt/anaconda3/lib/python3.8/site-packages/urllib3/connection.py", line 363, in connect
>    self.sock = conn = self._new_conn()
>  File "/opt/anaconda3/lib/python3.8/site-packages/urllib3/connection.py", line 186, in _new_conn
>    raise NewConnectionError(
> urllib3.exceptions.NewConnectionError: <urllib3.connection.HTTPSConnection object at 0x7fee78a79040>: Failed to establish a new connection: [Errno 61] Connection refused
> 
> During handling of the above exception, another exception occurred:
>
> Traceback (most recent call last):
>  File "loader.py", line 8, in <module>
>    print(f"Connected to ElasticSearch cluster `{es.info().body['cluster_name']}`")
>  File "/opt/anaconda3/lib/python3.8/site-packages/elasticsearch/client/utils.py", line 347, in _wrapped
>    return func(*args, params=params, headers=headers, **kwargs)
>  File "/opt/anaconda3/lib/python3.8/site-packages/elasticsearch/client/__init__.py", line 295, in info
>    return self.transport.perform_request(
>  File "/opt/anaconda3/lib/python3.8/site-packages/elasticsearch/transport.py", line 417, in perform_request
>    self._do_verify_elasticsearch(headers=headers, timeout=timeout)
>  File "/opt/anaconda3/lib/python3.8/site-packages/elasticsearch/transport.py", line 606, in _do_verify_elasticsearch
>    raise error
>  File "/opt/anaconda3/lib/python3.8/site-packages/elasticsearch/transport.py", line 569, in _do_verify_elasticsearch
>    _, info_headers, info_response = conn.perform_request(
>  File "/opt/anaconda3/lib/python3.8/site-packages/elasticsearch/connection/http_urllib3.py", line 280, in perform_request
>    raise ConnectionError("N/A", str(e), e)
> elasticsearch.exceptions.ConnectionError: ConnectionError(<urllib3.connection.HTTPSConnection object at 0x7fee78a79040>: Failed to establish a new connection: [Errno 61] Connection refused) caused by: NewConnectionError(<urllib3.connection.HTTPSConnection object at 0x7fee78a79040>: Failed to establish a new connection: [Errno 61] Connection refused)
> ```

